Workbook
Name category: Roadmap!$G1
Name category: #REF!
Name display_year: Roadmap!$S$2
Name duration: Roadmap!$F1
Name end_date: Roadmap!$E1
Name Milestone_Marker: #REF!
Name month: Roadmap!A$5
Name next_month: Roadmap!B$5
Name Project_Start: #REF!
Name project_start_date: Roadmap!$R$1
Name Scrolling_Increment: #REF!
Name start_date: Roadmap!$D1

Sheet Readme
B1: #VALUE!
G4: Counts
G5: 2026 | H5: 2027 | I5: 2028 | J5: 2029
G6: =COUNTIFS(Roadmap!$D:$D,"<="&DATE(2026,12,31),Roadmap!$E:$E,">="&DATE(2026,1,1)) -> 302 | H6: =COUNTIFS(Roadmap!$D:$D,"<="&DATE(2027,12,31),Roadmap!$E:$E,">="&DATE(2027,1,1)) -> 64 | I6: =COUNTIFS(Roadmap!$D:$D,"<="&DATE(2028,12,31),Roadmap!$E:$E,">="&DATE(2028,1,1)) -> 7 | J6: =COUNTIFS(Roadmap!$D:$D,"<="&DATE(2029,12,31),Roadmap!$E:$E,">="&DATE(2029,1,1)) -> 6
B8: What This Workbook Does | G8: Legend
B9: This workbook automatically consolidates Branch Calendar event dates, Youth Program Team work items and other reference dates into a dynamic, interactive roadmap. | G9: Event | H9: Branch Calendar Event | I9: Prep | J9: Comms | K9: Event
B10: It pulls live data from SharePoint, combines it with manually added dates from the Manual Dates sheet, formats task labels conditionally, and renders an interactive timeline that can be re-sorted on the fly without breaking formulas.
B12: Why It Was Built
B13: - Single Source of Truth: Eliminates manual data entry by syncing directly with external SharePoint lists.
B14: - Consolidated Visibility: Blends multiple sources into a unified view.
B15: - Interactive Filtering & Sorting: Allows users to re-sort timelines (by Start Date, Title, or Category) and separate Reference Dates/Milestones from important dates.
B16: - Automated Visuals: Uses conditional formatting to automatically draw timelines based on live entry dates.
B18: How It Operates
B19: Data Sources:
B20: - Branch Calendar feed from Members website - imported to the Youth Program Team SharePoint site and then connected to this workbook
B21: - "Manual Dates" - a sheet used to manually enter dates into the query. Initially includes school holidays for term planning references
B23: Power Query Layer (AllDates Table):
B24: Connects to the SharePoint list and local Manual Dates tables.
... B41: Adding New Tasks: Add new internal tasks directly to the Manual Dates table on the staging sheet. They will flow into the Gantt chart upon the next refresh.

Sheet Roadmap
B1: #VALUE! | D1: Sort by | L1: Start Date | O1: Starting at | R1: 46023
S2: 1
F4: To be hidden | G4: To be hidden | H4: To be hidden | I4: =YEAR(month) -> 2026 | U4: =YEAR(month) -> 2027 | AG4: =YEAR(month) -> 2028
B5: EVENT | C5: PROJECT / ACTION | D5: START DATE | E5: END DATE | F5: MONTHS | G5: CATEGORY | H5: TAGS | I5: =DATE(YEAR(project_start_date)+(display_year-1),1,1) -> 46023 | J5: =EDATE(I5,1) -> 46054 | K5: =EDATE(J5,1) -> 46082 | L5: =EDATE(K5,1) -> 46113 | M5: =EDATE(L5,1) -> 46143 | N5: =EDATE(M5,1) -> 46174 | O5: =EDATE(N5,1) -> 46204 | P5: =EDATE(O5,1) -> 46235 | Q5: =EDATE(P5,1) -> 46266 | ... AR5: =EDATE(AQ5,1) -> 47088
A6: 1 | B6: {=_xlfn.SORTBY(_xlfn._xlws.FILTER(AllDates[NewTitle], AllDates[Change Category]<>"Reference Date", ""), _xlfn.SWITCH($L$1, "Start Date", _xlfn._xlws.FILTER(AllDates[StartDate], AllDates[Change Category]<>"Reference Date", ""), "Task Name", _xlfn._xlws.FILTER(AllDates[NewTitle], AllDates[Change Category]<>"Reference Date", ""), "Category", _xlfn._xlws.FILTER(AllDates[Change Category], AllDates[Change Category]<>"Reference Date", ""), _xlfn._xlws.FILTER(AllDates[StartDate], AllDates[Change Category]<>"Reference Date", "")), 1)} -> Vertical - Abseiling Natural SP (Wide Bay) | C6: {=_xlfn.SORTBY( IF( _xlfn._xlws.FILTER(AllDates[OperationalActionTitle], AllDates[Change Category]<>"Reference Date", "")=0, "", _xlfn._xlws.FILTER(AllDates[OperationalActionTitle], AllDates[Change Category]<>"Reference Date", "") ), _xlfn.SWITCH( $L$1, "Start Date", _xlfn._xlws.FILTER(AllDates[StartDate], AllDates[Change Category]<>"Reference Date", ""), "Task Name", _xlfn._xlws.FILTER(AllDates[NewTitle], AllDates[Change Category]<>"Reference Date", ""), "Category", _xlfn._xlws.FILTER(AllDates[Change Category], AllDates[Change Category]<>"Reference Date", ""), _xlfn._xlws.FILTER(AllDates[StartDate], AllDates[Change Category]<>"Reference Date", "") ), 1 )} | D6: {=_xlfn.SORTBY(_xlfn._xlws.FILTER(AllDates[StartDate], AllDates[Change Category]<>"Reference Date", ""), _xlfn.SWITCH($L$1, "Start Date", _xlfn._xlws.FILTER(AllDates[StartDate], AllDates[Change Category]<>"Reference Date", ""), "Task Name", _xlfn._xlws.FILTER(AllDates[NewTitle], AllDates[Change Category]<>"Reference Date", ""), "Category", _xlfn._xlws.FILTER(AllDates[Change Category], AllDates[Change Category]<>"Reference Date", ""), _xlfn._xlws.FILTER(AllDates[StartDate], AllDates[Change Category]<>"Reference Date", "")), 1)} -> 46023 | E6: {=_xlfn.SORTBY(_xlfn._xlws.FILTER(AllDates[DueDate], AllDates[Change Category]<>"Reference Date", ""), _xlfn.SWITCH($L$1, "Start Date", _xlfn._xlws.FILTER(AllDates[StartDate], AllDates[Change Category]<>"Reference Date", ""), "Task Name", _xlfn._xlws.FILTER(AllDates[NewTitle], AllDates[Change Category]<>"Reference Date", ""), "Category", _xlfn._xlws.FILTER(AllDates[Change Category], AllDates[Change Category]<>"Reference Date", ""), _xlfn._xlws.FILTER(AllDates[StartDate], AllDates[Change Category]<>"Reference Date", "")), 1)} -> 46023 | F6: =IF(OR(ISBLANK(start_date),ISBLANK(end_date)),"",1+ROUND(((EOMONTH(end_date,0)-EOMONTH(start_date,0))/30),0)) -> 1 | G6: {=_xlfn.SORTBY(_xlfn._xlws.FILTER(AllDates[Change Category], AllDates[Change Category]<>"Reference Date", ""), _xlfn.SWITCH($L$1, "Start Date", _xlfn._xlws.FILTER(AllDates[StartDate], AllDates[Change Category]<>"Reference Date", ""), "Task Name", _xlfn._xlws.FILTER(AllDates[NewTitle], AllDates[Change Category]<>"Reference Date", ""), "Category", _xlfn._xlws.FILTER(AllDates[Change Category], AllDates[Change Category]<>"Reference Date", ""), _xlfn._xlws.FILTER(AllDates[StartDate], AllDates[Change Category]<>"Reference Date", "")), 1)} -> Branch Calendar Event | H6: {=_xlfn.SORTBY(_xlfn._xlws.FILTER(AllDates[Tags], AllDates[Change Category]<>"Reference Date", ""), _xlfn.SWITCH($L$1, "Start Date", _xlfn._xlws.FILTER(AllDates[StartDate], AllDates[Change Category]<>"Reference Date", ""), "Task Name", _xlfn._xlws.FILTER(AllDates[NewTitle], AllDates[Change Category]<>"Reference Date", ""), "Category", _xlfn._xlws.FILTER(AllDates[Change Category], AllDates[Change Category]<>"Reference Date", ""), _xlfn._xlws.FILTER(AllDates[StartDate], AllDates[Change Category]<>"Reference Date", "")), 1)} -> Training - AA
A7: 2 | B7: Basic Water Rescue (FNQ) | D7: 46023 | E7: 46023 | F7: =IF(OR(ISBLANK(start_date),ISBLANK(end_date)),"",1+ROUND(((EOMONTH(end_date,0)-EOMONTH(start_date,0))/30),0)) -> 1 | G7: Branch Calendar Event | H7: 0
A8: 3 | B8: Scouting Essentials (Brisbane) | D8: 46023 | E8: 46023 | F8: =IF(OR(ISBLANK(start_date),ISBLANK(end_date)),"",1+ROUND(((EOMONTH(end_date,0)-EOMONTH(start_date,0))/30),0)) -> 1 | G8: Branch Calendar Event | H8: Training - AA
A9: 4 | B9: Scouting Management - Group Leaders (Brisbane) | D9: 46023 | E9: 46023 | F9: =IF(OR(ISBLANK(start_date),ISBLANK(end_date)),"",1+ROUND(((EOMONTH(end_date,0)-EOMONTH(start_date,0))/30),0)) -> 1 | G9: Branch Calendar Event | H9: Training - AA
A10: 5 | B10: Paddling - Kayak Inland Flatwater TP (Wide Bay) | D10: 46024 | E10: 46024 | F10: =IF(OR(ISBLANK(start_date),ISBLANK(end_date)),"",1+ROUND(((EOMONTH(end_date,0)-EOMONTH(start_date,0))/30),0)) -> 1 | G10: Branch Calendar Event | H10: Training - AA
A11: 6 | B11: Paddling - SUP Inland Flatwater SP | D11: 46024 | E11: 46024 | F11: =IF(OR(ISBLANK(start_date),ISBLANK(end_date)),"",1+ROUND(((EOMONTH(end_date,0)-EOMONTH(start_date,0))/30),0)) -> 1 | G11: Branch Calendar Event | H11: Training - AA
A12: 7 | B12: Cycling - On Road - SP/TP (Wide Bay) | D12: 46029 | E12: 46029 | F12: =IF(OR(ISBLANK(start_date),ISBLANK(end_date)),"",1+ROUND(((EOMONTH(end_date,0)-EOMONTH(start_date,0))/30),0)) -> 1 | G12: Branch Calendar Event | H12: Training - AA
A13: 8 | B13: Cycling - On Road - SP/TP (Wide Bay) | D13: 46029 | E13: 46029 | F13: =IF(OR(ISBLANK(start_date),ISBLANK(end_date)),"",1+ROUND(((EOMONTH(end_date,0)-EOMONTH(start_date,0))/30),0)) -> 1 | G13: Branch Calendar Event | H13: Training - AA
A14: 9 | B14: Queensland Branch Rover Council Meeting | D14: 46039 | E14: 46039 | F14: =IF(OR(ISBLANK(start_date),ISBLANK(end_date)),"",1+ROUND(((EOMONTH(end_date,0)-EOMONTH(start_date,0))/30),0)) -> 1 | G14: Branch Calendar Event | H14: Rover Scouts
A15: 10 | B15: Branch Finance Committee | D15: 46040 | E15: 46040 | F15: =IF(OR(ISBLANK(start_date),ISBLANK(end_date)),"",1+ROUND(((EOMONTH(end_date,0)-EOMONTH(start_date,0))/30),0)) -> 1 | G15: Branch Calendar Event | H15: 0
A16: 11 | B16: Branch Joey Scout Council | D16: 46042 | E16: 46042 | F16: =IF(OR(ISBLANK(start_date),ISBLANK(end_date)),"",1+ROUND(((EOMONTH(end_date,0)-EOMONTH(start_date,0))/30),0)) -> 1 | G16: Branch Calendar Event | H16: Joey Scouts
A17: 12 | B17: Australia Day | D17: 46047 | E17: 46047 | F17: =IF(OR(ISBLANK(start_date),ISBLANK(end_date)),"",1+ROUND(((EOMONTH(end_date,0)-EOMONTH(start_date,0))/30),0)) -> 1 | G17: Branch Calendar Event | H17: 0
A18: 13 | B18: Branch Executive Committee | D18: 46048 | E18: 46048 | F18: =IF(OR(ISBLANK(start_date),ISBLANK(end_date)),"",1+ROUND(((EOMONTH(end_date,0)-EOMONTH(start_date,0))/30),0)) -> 1 | G18: Branch Calendar Event | H18: 0
A19: 14 | B19: Cycling - Off Road - SP/TP (Brisbane) | D19: 46057 | E19: 46057 | F19: =IF(OR(ISBLANK(start_date),ISBLANK(end_date)),"",1+ROUND(((EOMONTH(end_date,0)-EOMONTH(start_date,0))/30),0)) -> 1 | G19: Branch Calendar Event | H19: Training - AA
A20: 15 | B20: Scouting Leadership (Online) | D20: 46058 | E20: 46058 | F20: =IF(OR(ISBLANK(start_date),ISBLANK(end_date)),"",1+ROUND(((EOMONTH(end_date,0)-EOMONTH(start_date,0))/30),0)) -> 1 | G20: Branch Calendar Event | H20: Training - AA
A21: 16 | B21: Cycling - Off Road - SP/TP (Wide Bay) | D21: 46060 | E21: 46060 | F21: =IF(OR(ISBLANK(start_date),ISBLANK(end_date)),"",1+ROUND(((EOMONTH(end_date,0)-EOMONTH(start_date,0))/30),0)) -> 1 | G21: Branch Calendar Event | H21: Training - AA
A22: 17 | B22: Cycling - Off Road - SP/TP (Wide Bay) | D22: 46060 | E22: 46060 | F22: =IF(OR(ISBLANK(start_date),ISBLANK(end_date)),"",1+ROUND(((EOMONTH(end_date,0)-EOMONTH(start_date,0))/30),0)) -> 1 | G22: Branch Calendar Event | H22: 0
A23: 18 | B23: Scouting Adventure (Brisbane) | D23: 46062 | E23: 46121 | F23: =IF(OR(ISBLANK(start_date),ISBLANK(end_date)),"",1+ROUND(((EOMONTH(end_date,0)-EOMONTH(start_date,0))/30),0)) -> 3 | G23: Branch Calendar Event | H23: Training - AA
A24: 19 | B24: Scouting Essentials (Brisbane) | D24: 46062 | E24: 46121 | F24: =IF(OR(ISBLANK(start_date),ISBLANK(end_date)),"",1+ROUND(((EOMONTH(end_date,0)-EOMONTH(start_date,0))/30),0)) -> 3 | G24: Branch Calendar Event | H24: Training - AA
A25: 20 | B25: Scouting Adventure (Brisbane) | D25: 46062 | E25: 46121 | F25: =IF(OR(ISBLANK(start_date),ISBLANK(end_date)),"",1+ROUND(((EOMONTH(end_date,0)-EOMONTH(start_date,0))/30),0)) -> 3 | G25: Branch Calendar Event | H25: 0
A26: 21 | B26: Scouting Essentials (Brisbane) | D26: 46062 | E26: 46121 | F26: =IF(OR(ISBLANK(start_date),ISBLANK(end_date)),"",1+ROUND(((EOMONTH(end_date,0)-EOMONTH(start_date,0))/30),0)) -> 3 | G26: Branch Calendar Event | H26: 0
A27: 22 | B27: Queensland Branch Rover Council Meeting | D27: 46067 | E27: 46067 | F27: =IF(OR(ISBLANK(start_date),ISBLANK(end_date)),"",1+ROUND(((EOMONTH(end_date,0)-EOMONTH(start_date,0))/30),0)) -> 1 | G27: Branch Calendar Event | H27: Rover Scouts
A28: 23 | B28: Branch Finance Committee | D28: 46068 | E28: 46068 | F28: =IF(OR(ISBLANK(start_date),ISBLANK(end_date)),"",1+ROUND(((EOMONTH(end_date,0)-EOMONTH(start_date,0))/30),0)) -> 1 | G28: Branch Calendar Event | H28: 0
A29: 24 | B29: Branch Scout Section Council | D29: 46068 | E29: 46068 | F29: =IF(OR(ISBLANK(start_date),ISBLANK(end_date)),"",1+ROUND(((EOMONTH(end_date,0)-EOMONTH(start_date,0))/30),0)) -> 1 | G29: Branch Calendar Event | H29: 0
A30: 25 | B30: Branch Youth Venturer Scout Council | D30: 46070 | E30: 46070 | F30: =IF(OR(ISBLANK(start_date),ISBLANK(end_date)),"",1+ROUND(((EOMONTH(end_date,0)-EOMONTH(start_date,0))/30),0)) -> 1 | G30: Branch Calendar Event | H30: 0
A31: 26 | B31: Branch Joey Scout Council | D31: 46070 | E31: 46070 | F31: =IF(OR(ISBLANK(start_date),ISBLANK(end_date)),"",1+ROUND(((EOMONTH(end_date,0)-EOMONTH(start_date,0))/30),0)) -> 1 | G31: Branch Calendar Event | H31: Joey Scouts
A32: 27 | B32: Branch Cub Scout Section Team Meeting | D32: 46071 | E32: 46071 | F32: =IF(OR(ISBLANK(start_date),ISBLANK(end_date)),"",1+ROUND(((EOMONTH(end_date,0)-EOMONTH(start_date,0))/30),0)) -> 1 | G32: Branch Calendar Event | H32: 0
A33: 28 | B33: Founder's Day Dinner | D33: 46072 | E33: 46072 | F33: =IF(OR(ISBLANK(start_date),ISBLANK(end_date)),"",1+ROUND(((EOMONTH(end_date,0)-EOMONTH(start_date,0))/30),0)) -> 1 | G33: Branch Calendar Event | H33: 0
A34: 29 | B34: Scouting Adventure (Ipswich) | D34: 46072 | E34: 46074 | F34: =IF(OR(ISBLANK(start_date),ISBLANK(end_date)),"",1+ROUND(((EOMONTH(end_date,0)-EOMONTH(start_date,0))/30),0)) -> 1 | G34: Branch Calendar Event | H34: Training - AA
A35: 30 | B35: Scouting Adventure (Ipswich) | D35: 46072 | E35: 46074 | F35: =IF(OR(ISBLANK(start_date),ISBLANK(end_date)),"",1+ROUND(((EOMONTH(end_date,0)-EOMONTH(start_date,0))/30),0)) -> 1 | G35: Branch Calendar Event | H35: Training - AA
A36: 31 | B36: Synchronised Cub Scout Camp (local groups) | D36: 46072 | E36: 46074 | F36: =IF(OR(ISBLANK(start_date),ISBLANK(end_date)),"",1+ROUND(((EOMONTH(end_date,0)-EOMONTH(start_date,0))/30),0)) -> 1 | G36: Branch Calendar Event | H36: 0
A37: 32 | B37: Paddling - SUP Inland Flatwater SP/TP | D37: 46073 | E37: 46073 | F37: =IF(OR(ISBLANK(start_date),ISBLANK(end_date)),"",1+ROUND(((EOMONTH(end_date,0)-EOMONTH(start_date,0))/30),0)) -> 1 | G37: Branch Calendar Event | H37: Training - AA
A38: 33 | B38: Paddling - SUP Inland Flatwater SP/TP | D38: 46073 | E38: 46073 | F38: =IF(OR(ISBLANK(start_date),ISBLANK(end_date)),"",1+ROUND(((EOMONTH(end_date,0)-EOMONTH(start_date,0))/30),0)) -> 1 | G38: Branch Calendar Event | H38: Training - AA
A39: 34 | B39: Founder's Day | D39: 46074 | E39: 46074 | F39: =IF(OR(ISBLANK(start_date),ISBLANK(end_date)),"",1+ROUND(((EOMONTH(end_date,0)-EOMONTH(start_date,0))/30),0)) -> 1 | G39: Branch Calendar Event | H39: 0
A40: 35 | B40: ARA Nominations Deadline | D40: 46075 | E40: 46075 | F40: =IF(OR(ISBLANK(start_date),ISBLANK(end_date)),"",1+ROUND(((EOMONTH(end_date,0)-EOMONTH(start_date,0))/30),0)) -> 1 | G40: Branch Calendar Event | H40: 0
A41: 36 | B41: Scouting Essentials (Online) | D41: 46076 | E41: 46076 | F41: =IF(OR(ISBLANK(start_date),ISBLANK(end_date)),"",1+ROUND(((EOMONTH(end_date,0)-EOMONTH(start_date,0))/30),0)) -> 1 | G41: Branch Calendar Event | H41: Training - AA
...

Sheet Manual Dates
E1: ADD TO THIS SHEET TO AUTOMATICALLY ADD TO THE MASTER LISTING
A2: FileSystemObjectType | B2: Id | C2: ServerRedirectedEmbedUri | D2: ServerRedirectedEmbedUrl | E2: Title | F2: Description | G2: Priority | H2: Parent Work ItemId | I2: Category0 | J2: Progress | K2: StartDate | L2: DueDate | M2: AssignedTo0Id | N2: AssignedTo0StringId | O2: Notes | P2: KeyStakeholdersId | Q2: KeyStakeholdersStringId | R2: Location | S2: Tags | T2: CalendarID | U2: ContentTypeId | V2: OData__ColorTag | W2: ComplianceAssetId | X2: Operational ActionId | Y2: YPT Tag | Z2: Responsible | AA2: Change Category | AB2: Milestone | AC2: ID.1 | AD2: Modified | AE2: Created | AF2: AuthorId | AG2: EditorId | AH2: OData__UIVersionString | AI2: Attachments | AJ2: GUID | AK2: Title2 | AL2: District | AM2: Section
E3: School Holidays (April) | J3: Calendar Entry | K3: 46115 | L3: 46131 | AA3: Reference | AN3: Reference Date
E4: School Holidays (July) | J4: Calendar Entry | K4: 46200 | L4: 46217 | AA4: Reference | AN4: Reference Date
E5: School Holidays (September) | J5: Calendar Entry | K5: 46284 | L5: 46300 | AA5: Reference | AN5: Reference Date
E6: School Holidays (December) | J6: Calendar Entry | K6: 46368 | L6: 46413 | AA6: Reference | AN6: Reference Date
E7: School Holidays (April) | J7: Calendar Entry | K7: 46472 | L7: 46488 | AA7: Reference | AN7: Reference Date
E8: School Holidays (July) | J8: Calendar Entry | K8: 46564 | L8: 46579 | AA8: Reference | AN8: Reference Date
E9: School Holidays (September) | J9: Calendar Entry | K9: 46648 | L9: 46664 | AA9: Reference | AN9: Reference Date
E10: School Holidays (December) | J10: Calendar Entry | K10: 46732 | L10: 46775 | AA10: Reference | AN10: Reference Date
E11: School Holidays (April) | J11: Calendar Entry | K11: 46844 | L11: 46860 | AA11: Reference | AN11: Reference Date
E12: School Holidays (July) | J12: Calendar Entry | K12: 46928 | L12: 46943 | AA12: Reference | AN12: Reference Date
E13: School Holidays (September) | J13: Calendar Entry | K13: 47012 | L13: 47028 | AA13: Reference | AN13: Reference Date
E14: School Holidays (December) | J14: Calendar Entry | K14: 47096 | L14: 47139 | AA14: Reference | AN14: Reference Date
... E18: School Holidays (December) | J18: Calendar Entry | K18: 47460 | L18: 47483 | AA18: Reference | AN18: Reference Date
E19: ScoutFest 2027 | J19: Calendar Entry | K19: 46619 | L19: 46621 | AA19: Youth Program Event
E20: Easter 2027 | J20: Calendar Entry | K20: 46472 | L20: 46475 | AA20: Reference | AN20: Reference Date
E21: Easter 2028 | J21: Calendar Entry | K21: 46857 | L21: 46860 | AA21: Reference | AN21: Reference Date
E22: Easter 2029 | J22: Calendar Entry | K22: 47207 | L22: 47210 | AA22: Reference | AN22: Reference Date
E23: Skillorama | J23: Calendar Entry | K23: 46270 | L23: 46270 | AA23: Youth Program Event
E24: Joey Scout Hopalong | J24: Calendar Entry | K24: 46459 | L24: 46459 | AA24: Youth Program Event
E25: ScoutOut | J25: Calendar Entry | K25: 46319 | L25: 46320 | AA25: Youth Program Event
E26: Cub Scout Leader Expo | J26: Calendar Entry | K26: 46620 | L26: 46622 | AA26: Youth Program Event
E27: Nighthawk (Crows Nest) | J27: Calendar Entry | K27: 46613 | L27: 46614 | AA27: Youth Program Event
E28: Test N Track Moot | J28: Calendar Entry | K28: 46508 | L28: 46508 | AA28: Youth Program Event | AN28: Approx date only
E29: Banana Bash | J29: Calendar Entry | K29: 46661 | L29: 46661 | AA29: Youth Program Event | AN29: Approx date only
E30: QBRC Conference | J30: Calendar Entry | K30: 46447 | L30: 46447 | AA30: Youth Program Event | AN30: Approx date only
E31: QBRC Conference | J31: Calendar Entry | K31: 46692 | L31: 46692 | AA31: Youth Program Event | AN31: Approx date only
E32: Qld Rovers ARP | J32: Calendar Entry | K32: 46539 | L32: 46539 | AA32: Youth Program Event | AN32: Approx date only
E33: QBRC Conference | J33: Calendar Entry | K33: 46569 | L33: 46569 | AA33: Youth Program Event | AN33: Approx date only
E34: Banana Bash applications period | J34: Calendar Entry | K34: 46631 | L34: 46631 | AA34: Prep | AN34: Approx date only
E35: QARM | J35: Calendar Entry | K35: 46419 | L35: 46419 | AA35: Youth Program Event | AN35: Approx date only
E36: QARM applications period | J36: Calendar Entry | K36: 46357 | L36: 46418 | AA36: Prep | AN36: Approx date only
E37: QMoot | J37: Calendar Entry | K37: 46447 | L37: 46447 | AA37: Youth Program Event | AN37: Approx date only
E38: QMoot applications period | J38: Calendar Entry | K38: 46388 | L38: 46446 | AA38: Prep | AN38: Approx date only
E39: Urban Challenge | J39: Calendar Entry | K39: 46508 | L39: 46508 | AA39: Youth Program Event | AN39: Approx date only
... E41: RoVenture | J41: Calendar Entry | K41: 46569 | L41: 46569 | AA41: Youth Program Event | AN41: Approx date only
E42: RoVenture applications period | J42: Calendar Entry | K42: 46539 | L42: 46539 | AA42: Prep | AN42: Approx date only | AQ42: In relation to key dates:
E43: St George's Ball | J43: Calendar Entry | K43: 46631 | L43: 46631 | AA43: Youth Program Event | AN43: Approx date only | AQ43: 1. Committee appointed – 12 months out
E44: St George's Ball ticket purchasing period | J44: Calendar Entry | K44: 46600 | L44: 46600 | AA44: Prep | AN44: Approx date only | AQ44: 2. Budget Approved - 4 months out
...

Sheet 2027 Weekly Planner
A1: Queensland 2027 School Terms and Public Holidays Planner
A2: Weekly planning view. Queensland state school terms, school holidays, student-free days and Queensland public holidays, including the Brisbane Show Holiday.
A4: Category | B4: Special date or period | C4: Start | D4: End | E4: W53 28 Dec | F4: W1 04 Jan | G4: W2 11 Jan | H4: W3 18 Jan | I4: W4 25 Jan | J4: W5 01 Feb | K4: W6 08 Feb | L4: W7 15 Feb | M4: W8 22 Feb | N4: W9 01 Mar | O4: W10 08 Mar | P4: W11 15 Mar | Q4: W12 22 Mar | R4: W13 29 Mar | S4: W14 05 Apr | T4: W15 12 Apr | U4: W16 19 Apr | V4: W17 26 Apr | W4: W18 03 May | X4: W19 10 May | Y4: W20 17 May | Z4: W21 24 May | AA4: W22 31 May | AB4: W23 07 Jun | AC4: W24 14 Jun | AD4: W25 21 Jun | AE4: W26 28 Jun | AF4: W27 05 Jul | AG4: W28 12 Jul | AH4: W29 19 Jul | AI4: W30 26 Jul | AJ4: W31 02 Aug | AK4: W32 09 Aug | AL4: W33 16 Aug | AM4: W34 23 Aug | AN4: W35 30 Aug | AO4: W36 06 Sep | AP4: W37 13 Sep | AQ4: W38 20 Sep | AR4: W39 27 Sep | AS4: W40 04 Oct | AT4: W41 11 Oct | AU4: W42 18 Oct | AV4: W43 25 Oct | AW4: W44 01 Nov | AX4: W45 08 Nov | AY4: W46 15 Nov | AZ4: W47 22 Nov | BA4: W48 29 Nov | BB4: W49 06 Dec | BC4: W50 13 Dec | BD4: W51 20 Dec | BE4: W52 27 Dec
A5: Queensland public holiday | B5: New Year's Day | C5: 46388 | D5: 46388 | E5: 01 Jan
A6: Student-free day | B6: Professional development day | C6: 46408 | D6: 46408 | H6: 21 Jan
A7: Student-free day | B7: Professional development day | C7: 46409 | D7: 46409 | H7: 22 Jan
A8: Student-free day | B8: Professional development day | C8: 46412 | D8: 46412 | I8: 25 Jan
A9: Queensland public holiday | B9: Australia Day | C9: 46413 | D9: 46413 | I9: 26 Jan
A10: School term | B10: Term 1 | C10: 46414 | D10: 46471 | I10: 27–31 Jan | J10: 01–07 Feb | K10: 08–14 Feb | L10: 15–21 Feb | M10: 22–28 Feb | N10: 01–07 Mar | O10: 08–14 Mar | P10: 15–21 Mar | Q10: 22–25 Mar
B11: Term 1 - YPT Program Conference "Supporting Change"
A12: School holidays | B12: Term 1 school holidays | C12: 46472 | D12: 46488 | Q12: 26–28 Mar | R12: 29–04 Apr | S12: 05–11 Apr
A13: Queensland public holiday | B13: Good Friday | C13: 46472 | D13: 46472 | Q13: 26 Mar
A14: Queensland public holiday | B14: The day after Good Friday | C14: 46473 | D14: 46473 | Q14: 27 Mar
A15: Queensland public holiday | B15: Easter Sunday | C15: 46474 | D15: 46474 | Q15: 28 Mar
A16: Queensland public holiday | B16: Easter Monday | C16: 46475 | D16: 46475 | R16: 29 Mar
A17: Student-free day | B17: Professional development day | C17: 46485 | D17: 46485 | S17: 08 Apr
A18: Student-free day | B18: Professional development day | C18: 46486 | D18: 46486 | S18: 09 Apr
A19: School term | B19: Term 2 | C19: 46489 | D19: 46563 | T19: 12–18 Apr | U19: 19–25 Apr | V19: 26–02 May | W19: 03–09 May | X19: 10–16 May | Y19: 17–23 May | Z19: 24–30 May | AA19: 31–06 Jun | AB19: 07–13 Jun | AC19: 14–20 Jun | AD19: 21–25 Jun
A20: Queensland public holiday | B20: Anzac Day holiday | C20: 46503 | D20: 46503 | V20: 26 Apr
A21: Queensland public holiday | B21: Labour Day | C21: 46510 | D21: 46510 | W21: 03 May
A22: School holidays | B22: Term 2 school holidays | C22: 46564 | D22: 46579 | AD22: 26–27 Jun | AE22: 28–04 Jul | AF22: 05–11 Jul
A23: School term | B23: Term 3 | C23: 46580 | D23: 46647 | AG23: 12–18 Jul | AH23: 19–25 Jul | AI23: 26–01 Aug | AJ23: 02–08 Aug | AK23: 09–15 Aug | AL23: 16–22 Aug | AM23: 23–29 Aug | AN23: 30–05 Sep | AO23: 06–12 Sep | AP23: 13–17 Sep
A24: Brisbane public holiday | B24: Royal Queensland Show, Brisbane area only | C24: 46610 | D24: 46610 | AK24: 11 Aug
B25: Term 3 - YPT Program Conference
A26: Student-free day | B26: Professional development day | C26: 46633 | D26: 46633 | AN26: 03 Sep
A27: School holidays | B27: Term 3 school holidays | C27: 46648 | D27: 46664 | AP27: 18–19 Sep | AQ27: 20–26 Sep | AR27: 27–03 Oct | AS27: 04 Oct
A28: Queensland public holiday | B28: King's Birthday | C28: 46664 | D28: 46664 | AS28: 04 Oct
A29: School term | B29: Term 4 | C29: 46665 | D29: 46731 | AS29: 05–10 Oct | AT29: 11–17 Oct | AU29: 18–24 Oct | AV29: 25–31 Oct | AW29: 01–07 Nov | AX29: 08–14 Nov | AY29: 15–21 Nov | AZ29: 22–28 Nov | BA29: 29–05 Dec | BB29: 06–10 Dec
A30: School holidays | B30: Term 4 school holidays | C30: 46732 | D30: 46775 | BB30: 11–12 Dec | BC30: 13–19 Dec | BD30: 20–26 Dec | BE30: 27–02 Jan
A31: Queensland part-day holiday | B31: Christmas Eve, 6 pm to midnight | C31: 46745 | D31: 46745 | BD31: 24 Dec
A32: Queensland public holiday | B32: Christmas Day | C32: 46746 | D32: 46746 | BD32: 25 Dec
A33: Queensland public holiday | B33: Boxing Day | C33: 46747 | D33: 46747 | BD33: 26 Dec
A34: Queensland public holiday | B34: Christmas Day holiday | C34: 46748 | D34: 46748 | BE34: 27 Dec
A35: Queensland public holiday | B35: Boxing Day holiday | C35: 46749 | D35: 46749 | BE35: 28 Dec
A37: Legend
A38: School term
A39: School holidays
A40: Student-free day
A41: Queensland public holiday
A42: Brisbane public holiday

Sheet Dates and Sources
A1: 2027 Dates and Sources
A3: Category | B3: Event | C3: Start date | D3: End date | E3: Duration or note | F3: Source | G3: Planning note
A4: School term | B4: Term 1 | C4: 46414 | D4: 46471 | E4: 58 | F4: https://education.qld.gov.au/about-us/calendar/future-dates
A5: School holidays | B5: Term 1 school holidays | C5: 46472 | D5: 46488 | E5: 17 | F5: https://education.qld.gov.au/about-us/calendar/future-dates
A6: School term | B6: Term 2 | C6: 46489 | D6: 46563 | E6: 75 | F6: https://education.qld.gov.au/about-us/calendar/future-dates
A7: School holidays | B7: Term 2 school holidays | C7: 46564 | D7: 46579 | E7: 16 | F7: https://education.qld.gov.au/about-us/calendar/future-dates
A8: School term | B8: Term 3 | C8: 46580 | D8: 46647 | E8: 68 | F8: https://education.qld.gov.au/about-us/calendar/future-dates
A9: School holidays | B9: Term 3 school holidays | C9: 46648 | D9: 46664 | E9: 17 | F9: https://education.qld.gov.au/about-us/calendar/future-dates
A10: School term | B10: Term 4 | C10: 46665 | D10: 46731 | E10: 67 | F10: https://education.qld.gov.au/about-us/calendar/future-dates
A11: School holidays | B11: Term 4 school holidays | C11: 46732 | D11: 46775 | E11: 44 | F11: https://education.qld.gov.au/about-us/calendar/future-dates
A12: Student-free day | B12: Professional development day | C12: 46408 | D12: 46408 | E12: 1 | F12: https://education.qld.gov.au/about-us/calendar/future-dates
A13: Student-free day | B13: Professional development day | C13: 46409 | D13: 46409 | E13: 1 | F13: https://education.qld.gov.au/about-us/calendar/future-dates
A14: Student-free day | B14: Professional development day | C14: 46412 | D14: 46412 | E14: 1 | F14: https://education.qld.gov.au/about-us/calendar/future-dates
A15: Student-free day | B15: Professional development day | C15: 46485 | D15: 46485 | E15: 1 | F15: https://education.qld.gov.au/about-us/calendar/future-dates
... A25: Queensland public holiday | B25: Labour Day | C25: 46510 | D25: 46510 | E25: 1 | F25: https://www.qld.gov.au/recreation/travel/holidays/public
A26: Brisbane public holiday | B26: Royal Queensland Show, Brisbane area only | C26: 46610 | D26: 46610 | E26: 1 | F26: https://www.qld.gov.au/recreation/travel/holidays/public | G26: Local show holidays outside Brisbane vary by area and should be checked separately.
A27: Queensland public holiday | B27: King's Birthday | C27: 46664 | D27: 46664 | E27: 1 | F27: https://www.qld.gov.au/recreation/travel/holidays/public
A28: Queensland part-day holiday | B28: Christmas Eve, 6 pm to midnight | C28: 46745 | D28: 46745 | E28: 1 | F28: https://www.qld.gov.au/recreation/travel/holidays/public
A29: Queensland public holiday | B29: Christmas Day | C29: 46746 | D29: 46746 | E29: 1 | F29: https://www.qld.gov.au/recreation/travel/holidays/public
A30: Queensland public holiday | B30: Boxing Day | C30: 46747 | D30: 46747 | E30: 1 | F30: https://www.qld.gov.au/recreation/travel/holidays/public
A31: Queensland public holiday | B31: Christmas Day holiday | C31: 46748 | D31: 46748 | E31: 1 | F31: https://www.qld.gov.au/recreation/travel/holidays/public
A32: Queensland public holiday | B32: Boxing Day holiday | C32: 46749 | D32: 46749 | E32: 1 | F32: https://www.qld.gov.au/recreation/travel/holidays/public
A34: Scope note | B34: Queensland state school dates are used. Independent and Catholic school dates may vary. The Brisbane show holiday is included because planning is Brisbane-based. Other local show and special holidays are not included.

Sheet AllDates
A1: DO NOT EDIT THIS SHEET - AUTOMATICALLY UPDATES FROM A QUERY
A2: FileSystemObjectType | B2: Id | C2: ServerRedirectedEmbedUri | D2: ServerRedirectedEmbedUrl | E2: Title | F2: Description | G2: Priority | H2: Parent Work ItemId | I2: Category0 | J2: Progress | K2: StartDate | L2: DueDate | M2: AssignedTo0Id | N2: AssignedTo0StringId | O2: Notes | P2: KeyStakeholdersId | Q2: KeyStakeholdersStringId | R2: Location | S2: Tags | T2: CalendarID | U2: ContentTypeId | V2: OData__ColorTag | W2: ComplianceAssetId | X2: Operational ActionId | Y2: YPT Tag | Z2: Responsible | AA2: Change Category | AB2: Milestone | AC2: ID.1 | AD2: Modified | AE2: Created | AF2: AuthorId | AG2: EditorId | AH2: OData__UIVersionString | AI2: Attachments | AJ2: GUID | AK2: FirstUniqueAncestorSecurableObject | AL2: RoleAssignments | AM2: AttachmentFiles | AN2: ContentType | AO2: GetDlpPolicyTip | AP2: FieldValuesAsHtml | AQ2: FieldValuesAsText | AR2: FieldValuesForEdit | AS2: File | AT2: Folder | AU2: LikedByInformation | AV2: ParentList | AW2: Properties | AX2: Versions | AY2: Parent Work Item | AZ2: AssignedTo0 | BA2: KeyStakeholders | BB2: Operational Action | BC2: Author | BD2: Editor | BE2: Title2 | BF2: District | BG2: Section | BH2: OperationalActionTitle | BI2: NewTitle
A3: 0 | B3: 1072 | E3: Vertical - Abseiling Natural SP (Wide Bay) | F3: Applications Close: 06/03/2026 Course Number: 0 Course Fee: $ 155.00 Pre requisites: Adult Supporters, Adult Leaders, Rover Scouts, Venturer Scouts Click here for the Training Program Outline Click here to apply for this training course This program will provide fundamental skills and knowledge for abseiling on single pitches. Note: Times listed are indicative only and will be confirmed pre-course. | G3: Low | J3: Calendar Entry | K3: 46023 | L3: 46023 | P3: [List] | Q3: [List] | S3: Training - AA | T3: 7492 | U3: 0x01006B96C2D89248E44D9DCCC3EFE7C6F01F009AE4A35CBC209B4AAB88D9DE8B191F78 | AA3: Branch Calendar Event | AC3: 1072 | AD3: 46221 | AE3: 46161 | AF3: 102 | AG3: 102 | AH3: 4.0 | AI3: FALSE | AJ3: c7e7823e-a6be-4037-8d14-5ec480681593 | AK3: [Record] | AL3: [Table] | AM3: [Table] | AN3: [Record] | AO3: [Record] | AP3: [Record] | AQ3: [Record] | AR3: [Record] | AS3: [Record] | AT3: [Record] | AU3: [Record] | AV3: [Record] | AW3: [Record] | AX3: [Table] | AY3: [Record] | AZ3: [Record] | BA3: [Table] | BB3: [Record] | BC3: [Record] | BD3: [Record] | BI3: Vertical - Abseiling Natural SP (Wide Bay)
A4: 0 | B4: 1071 | E4: Basic Water Rescue (FNQ) | F4: Applications Close: 23/10/2026 Course Number: 2000SK2605 Course Fee: $ 55 Pre requisites: Adult Supporters, Adult Leaders, Rover Scouts, Venturer Scouts Click here to apply for this training course This program will provide skills and knowledge required to perform basic water rescues in indoor and outdoor aquatic venues Note: Times listed are indicative only and will be confirmed pre-course. | G4: Low | J4: Calendar Entry | K4: 46023 | L4: 46023 | P4: [List] | Q4: [List] | T4: 7491 | U4: 0x01006B96C2D89248E44D9DCCC3EFE7C6F01F009AE4A35CBC209B4AAB88D9DE8B191F78 | AA4: Branch Calendar Event | AC4: 1071 | AD4: 46221 | AE4: 46161 | AF4: 102 | AG4: 102 | AH4: 4.0 | AI4: FALSE | AJ4: 81d4efc5-230a-4046-a5d6-d59d21a6eefc | AK4: [Record] | AL4: [Table] | AM4: [Table] | AN4: [Record] | AO4: [Record] | AP4: [Record] | AQ4: [Record] | AR4: [Record] | AS4: [Record] | AT4: [Record] | AU4: [Record] | AV4: [Record] | AW4: [Record] | AX4: [Table] | AY4: [Record] | AZ4: [Record] | BA4: [Table] | BB4: [Record] | BC4: [Record] | BD4: [Record] | BI4: Basic Water Rescue (FNQ)
A5: 0 | B5: 1070 | E5: Scouting Essentials (Brisbane) | F5: Applications Close: 30/10/2026 Course Number: 1002616 Course Fee: $ 170.00 Pre requisites: Certificate of Adult Membership - Adult Leaders, Rover Scouts Click here for the Training Program Outline Click here to apply for this training course This program will provide the skills and knowledge needed to plan and deliver activities to implement the Youth Program at weekly meetings and overnight activities. Note: Times listed are indicative only, refer to final course documentation for your course for confirmed course times. | G5: Low | J5: Calendar Entry | K5: 46023 | L5: 46023 | P5: [List] | Q5: [List] | S5: Training - AA | T5: 7490 | U5: 0x01006B96C2D89248E44D9DCCC3EFE7C6F01F009AE4A35CBC209B4AAB88D9DE8B191F78 | AA5: Branch Calendar Event | AC5: 1070 | AD5: 46221 | AE5: 46161 | AF5: 102 | AG5: 102 | AH5: 4.0 | AI5: FALSE | AJ5: 459fc94c-7c66-4673-b739-2153a8c3e040 | AK5: [Record] | AL5: [Table] | AM5: [Table] | AN5: [Record] | AO5: [Record] | AP5: [Record] | AQ5: [Record] | AR5: [Record] | AS5: [Record] | AT5: [Record] | AU5: [Record] | AV5: [Record] | AW5: [Record] | AX5: [Table] | AY5: [Record] | AZ5: [Record] | BA5: [Table] | BB5: [Record] | BC5: [Record] | BD5: [Record] | BI5: Scouting Essentials (Brisbane)
A6: 0 | B6: 1069 | E6: Scouting Management - Group Leaders (Brisbane) | F6: Applications Close: 30/10/2026 Course Number: 1202605 Course Fee: $ 170.00 Pre requisites: Scouting Essentials and completion of Scouting Management On Demand learning Click here for the Training Program Outline Click here to apply for this training course This program will provide leaders of adults the skills and knowledge needed to manage and administer a formation at a group level to support the delivery of youth program. Note: This is the same curriculum as Scouting Management (for Commissioners and Advisers) but with Group Leader relevant examples Note: Times listed are indicative only, refer to final course documentation of your course for confirmed course times. | G6: Low | J6: Calendar Entry | K6: 46023 | L6: 46023 | P6: [List] | Q6: [List] | S6: Training - AA | T6: 7489 | U6: 0x01006B96C2D89248E44D9DCCC3EFE7C6F01F009AE4A35CBC209B4AAB88D9DE8B191F78 | AA6: Branch Calendar Event | AC6: 1069 | AD6: 46221 | AE6: 46161 | AF6: 102 | AG6: 102 | AH6: 4.0 | AI6: FALSE | AJ6: 769eb2e6-5ad7-4a79-ab38-b6856282b9f1 | AK6: [Record] | AL6: [Table] | AM6: [Table] | AN6: [Record] | AO6: [Record] | AP6: [Record] | AQ6: [Record] | AR6: [Record] | AS6: [Record] | AT6: [Record] | AU6: [Record] | AV6: [Record] | AW6: [Record] | AX6: [Table] | AY6: [Record] | AZ6: [Record] | BA6: [Table] | BB6: [Record] | BC6: [Record] | BD6: [Record] | BI6: Scouting Management - Group Leaders (Brisbane)
A7: 0 | B7: 1020 | E7: Paddling - Kayak Inland Flatwater TP (Wide Bay) | F7: Applications Close: 06/02/2026 Course Number: 0 Course Fee: $ 155 Pre requisites: Kayaking Flat Water Safe Participant (SP) appointment Click here for the Training Program Outline Click here to apply for this training course This program will provide skills and knowledge to paddle a kayak on inland flat water, including rescue following capsize. Note: Times listed are indicative only and will be confirmed pre-course. | G7: Low | J7: Calendar Entry | K7: 46024 | L7: 46024 | P7: [List] | Q7: [List] | S7: Training - AA | T7: 7192 | U7: 0x01006B96C2D89248E44D9DCCC3EFE7C6F01F009AE4A35CBC209B4AAB88D9DE8B191F78 | AA7: Branch Calendar Event | AC7: 1020 | AD7: 46221 | AE7: 46161 | AF7: 102 | AG7: 102 | AH7: 4.0 | AI7: FALSE | AJ7: a1c89867-3431-47b7-a903-bdb7e4566796 | AK7: [Record] | AL7: [Table] | AM7: [Table] | AN7: [Record] | AO7: [Record] | AP7: [Record] | AQ7: [Record] | AR7: [Record] | AS7: [Record] | AT7: [Record] | AU7: [Record] | AV7: [Record] | AW7: [Record] | AX7: [Table] | AY7: [Record] | AZ7: [Record] | BA7: [Table] | BB7: [Record] | BC7: [Record] | BD7: [Record] | BI7: Paddling - Kayak Inland Flatwater TP (Wide Bay)
A8: 0 | B8: 1015 | E8: Paddling - SUP Inland Flatwater SP | F8: Applications Close: 06/02/2025 Course Number: 2405SP2602 Course Fee: $ 80.00 Pre requisites: N/A Click here to apply for this training course This program will provide skills and knowledge to paddle a stand-up paddle board on inland flat water. Note: Times listed are indicative only and will be confirmed pre-course. | G8: Low | J8: Calendar Entry | K8: 46024 | L8: 46024 | P8: [List] | Q8: [List] | S8: Training - AA | T8: 7162 | U8: 0x01006B96C2D89248E44D9DCCC3EFE7C6F01F009AE4A35CBC209B4AAB88D9DE8B191F78 | AA8: Branch Calendar Event | AC8: 1015 | AD8: 46221 | AE8: 46161 | AF8: 102 | AG8: 102 | AH8: 4.0 | AI8: FALSE | AJ8: 3ed99ff7-54d4-4304-8e5c-61354d82ea38 | AK8: [Record] | AL8: [Table] | AM8: [Table] | AN8: [Record] | AO8: [Record] | AP8: [Record] | AQ8: [Record] | AR8: [Record] | AS8: [Record] | AT8: [Record] | AU8: [Record] | AV8: [Record] | AW8: [Record] | AX8: [Table] | AY8: [Record] | AZ8: [Record] | BA8: [Table] | BB8: [Record] | BC8: [Record] | BD8: [Record] | BI8: Paddling - SUP Inland Flatwater SP
A9: 0 | B9: 1024 | E9: Cycling - On Road - SP/TP (Wide Bay) | F9: Applications Close: 10/07/2026 Course Number: 0 Course Fee: $ 90.00 Pre requisites: Ability to ride a bike - Adult Supporters, Adult Leaders, Rover Scouts, Venturer Scouts Click here for the Training Program Outline Click here to apply for this training course This program will provide skills and knowledge to setup, maintain and repair a bicycle; plan routes; and ride on pathways and roads with easy to intermediate conditions (including rail trails). Note: Times listed are indicative only and will be confirmed pre-course. | G9: Low | J9: Calendar Entry | K9: 46029 | L9: 46029 | P9: [List] | Q9: [List] | S9: Training - AA | T9: 7237 | U9: 0x01006B96C2D89248E44D9DCCC3EFE7C6F01F009AE4A35CBC209B4AAB88D9DE8B191F78 | AA9: Branch Calendar Event | AC9: 1024 | AD9: 46221 | AE9: 46161 | AF9: 102 | AG9: 102 | AH9: 4.0 | AI9: FALSE | AJ9: c453b12a-b063-41d7-b6f3-0df5d2a8c32d | AK9: [Record] | AL9: [Table] | AM9: [Table] | AN9: [Record] | AO9: [Record] | AP9: [Record] | AQ9: [Record] | AR9: [Record] | AS9: [Record] | AT9: [Record] | AU9: [Record] | AV9: [Record] | AW9: [Record] | AX9: [Table] | AY9: [Record] | AZ9: [Record] | BA9: [Table] | BB9: [Record] | BC9: [Record] | BD9: [Record] | BI9: Cycling - On Road - SP/TP (Wide Bay)
A10: 0 | B10: 1047 | E10: Cycling - On Road - SP/TP (Wide Bay) | F10: Applications Close: 10/07/2026 Course Number: 0 Course Fee: $ 90.00 Pre requisites: Ability to ride a bike - Adult Supporters, Adult Leaders, Rover Scouts, Venturer Scouts Click here for the Training Program Outline Click here to apply for this training course This program will provide skills and knowledge to setup, maintain and repair a bicycle; plan routes; and ride on pathways and roads with easy to intermediate conditions (including rail trails). Note: Times listed are indicative only and will be confirmed pre-course. | G10: Low | J10: Calendar Entry | K10: 46029 | L10: 46029 | P10: [List] | Q10: [List] | S10: Training - AA | T10: 7385 | U10: 0x01006B96C2D89248E44D9DCCC3EFE7C6F01F009AE4A35CBC209B4AAB88D9DE8B191F78 | AA10: Branch Calendar Event | AC10: 1047 | AD10: 46221 | AE10: 46161 | AF10: 102 | AG10: 102 | AH10: 4.0 | AI10: FALSE | AJ10: 30539b2e-d445-48c3-ad9c-cd6b8bebca4d | AK10: [Record] | AL10: [Table] | AM10: [Table] | AN10: [Record] | AO10: [Record] | AP10: [Record] | AQ10: [Record] | AR10: [Record] | AS10: [Record] | AT10: [Record] | AU10: [Record] | AV10: [Record] | AW10: [Record] | AX10: [Table] | AY10: [Record] | AZ10: [Record] | BA10: [Table] | BB10: [Record] | BC10: [Record] | BD10: [Record] | BI10: Cycling - On Road - SP/TP (Wide Bay)
A11: 0 | B11: 991 | E11: Queensland Branch Rover Council Meeting | F11: Monthly | G11: Low | J11: Calendar Entry | K11: 46039 | L11: 46039 | P11: [List] | Q11: [List] | S11: Rover Scouts | T11: 5781 | U11: 0x01006B96C2D89248E44D9DCCC3EFE7C6F01F009AE4A35CBC209B4AAB88D9DE8B191F78 | AA11: Branch Calendar Event | AC11: 991 | AD11: 46221 | AE11: 46161 | AF11: 102 | AG11: 102 | AH11: 4.0 | AI11: FALSE | AJ11: 6e36a8f2-39f9-4aa3-ab20-a3c59bc739b4 | AK11: [Record] | AL11: [Table] | AM11: [Table] | AN11: [Record] | AO11: [Record] | AP11: [Record] | AQ11: [Record] | AR11: [Record] | AS11: [Record] | AT11: [Record] | AU11: [Record] | AV11: [Record] | AW11: [Record] | AX11: [Table] | AY11: [Record] | AZ11: [Record] | BA11: [Table] | BB11: [Record] | BC11: [Record] | BD11: [Record] | BI11: Queensland Branch Rover Council Meeting
A12: 0 | B12: 950 | E12: Branch Finance Committee | F12: 3rd Monday of the month | G12: Low | J12: Calendar Entry | K12: 46040 | L12: 46040 | P12: [List] | Q12: [List] | T12: 5740 | U12: 0x01006B96C2D89248E44D9DCCC3EFE7C6F01F009AE4A35CBC209B4AAB88D9DE8B191F78 | AA12: Branch Calendar Event | AC12: 950 | AD12: 46221 | AE12: 46161 | AF12: 102 | AG12: 102 | AH12: 4.0 | AI12: FALSE | AJ12: f79a5a36-74d0-4834-986f-adad3b2b8561 | AK12: [Record] | AL12: [Table] | AM12: [Table] | AN12: [Record] | AO12: [Record] | AP12: [Record] | AQ12: [Record] | AR12: [Record] | AS12: [Record] | AT12: [Record] | AU12: [Record] | AV12: [Record] | AW12: [Record] | AX12: [Table] | AY12: [Record] | AZ12: [Record] | BA12: [Table] | BB12: [Record] | BC12: [Record] | BD12: [Record] | BI12: Branch Finance Committee
A13: 0 | B13: 962 | E13: Branch Joey Scout Council | G13: Low | J13: Calendar Entry | K13: 46042 | L13: 46042 | P13: [List] | Q13: [List] | S13: Joey Scouts | T13: 5752 | U13: 0x01006B96C2D89248E44D9DCCC3EFE7C6F01F009AE4A35CBC209B4AAB88D9DE8B191F78 | Z13: BC Joey Scouts | AA13: Branch Calendar Event | AC13: 962 | AD13: 46221 | AE13: 46161 | AF13: 102 | AG13: 102 | AH13: 5.0 | AI13: FALSE | AJ13: 3121f1a5-ce81-4b71-b084-2377869ed28d | AK13: [Record] | AL13: [Table] | AM13: [Table] | AN13: [Record] | AO13: [Record] | AP13: [Record] | AQ13: [Record] | AR13: [Record] | AS13: [Record] | AT13: [Record] | AU13: [Record] | AV13: [Record] | AW13: [Record] | AX13: [Table] | AY13: [Record] | AZ13: [Record] | BA13: [Table] | BB13: [Record] | BC13: [Record] | BD13: [Record] | BI13: Branch Joey Scout Council
A14: 0 | B14: 913 | E14: Australia Day | F14: Yearly | G14: Low | J14: Calendar Entry | K14: 46047 | L14: 46047 | P14: [List] | Q14: [List] | T14: 5702 | U14: 0x01006B96C2D89248E44D9DCCC3EFE7C6F01F009AE4A35CBC209B4AAB88D9DE8B191F78 | AA14: Branch Calendar Event | AC14: 913 | AD14: 46221 | AE14: 46161 | AF14: 102 | AG14: 102 | AH14: 4.0 | AI14: FALSE | AJ14: 608ffe48-ebf8-448f-8f9e-30c3177ef533 | AK14: [Record] | AL14: [Table] | AM14: [Table] | AN14: [Record] | AO14: [Record] | AP14: [Record] | AQ14: [Record] | AR14: [Record] | AS14: [Record] | AT14: [Record] | AU14: [Record] | AV14: [Record] | AW14: [Record] | AX14: [Table] | AY14: [Record] | AZ14: [Record] | BA14: [Table] | BB14: [Record] | BC14: [Record] | BD14: [Record] | BI14: Australia Day
A15: 0 | B15: 938 | E15: Branch Executive Committee | F15: 4th Tuesday of the month (3rd Tuesday in December) | G15: Low | J15: Calendar Entry | K15: 46048 | L15: 46048 | P15: [List] | Q15: [List] | T15: 5728 | U15: 0x01006B96C2D89248E44D9DCCC3EFE7C6F01F009AE4A35CBC209B4AAB88D9DE8B191F78 | AA15: Branch Calendar Event | AC15: 938 | AD15: 46221 | AE15: 46161 | AF15: 102 | AG15: 102 | AH15: 4.0 | AI15: FALSE | AJ15: 6f0e39ee-1f10-4eb3-aadf-930fcc81c996 | AK15: [Record] | AL15: [Table] | AM15: [Table] | AN15: [Record] | AO15: [Record] | AP15: [Record] | AQ15: [Record] | AR15: [Record] | AS15: [Record] | AT15: [Record] | AU15: [Record] | AV15: [Record] | AW15: [Record] | AX15: [Table] | AY15: [Record] | AZ15: [Record] | BA15: [Table] | BB15: [Record] | BC15: [Record] | BD15: [Record] | BI15: Branch Executive Committee
A16: 0 | B16: 1037 | E16: Cycling - Off Road - SP/TP (Brisbane) | F16: Applications Close: 10/04/2026 Course Number: 2301PR2601 Course Fee: $ 90.00 Pre requisites: Ability to ride a bike - Adult Supporters, Adult Leaders, Rover Scouts, Venturer Scouts Click here for the Training Program Outline Click here to apply for this training course This program will provide skills and knowledge to setup, maintain and repair a bicycle; plan routes; and ride off-road bicycles on easy to intermediate trails (eg mountain bike trails). Note: Times listed are indicative only and will be confirmed pre-course. | G16: Low | J16: Calendar Entry | K16: 46057 | L16: 46057 | P16: [List] | Q16: [List] | S16: Training - AA | T16: 7367 | U16: 0x01006B96C2D89248E44D9DCCC3EFE7C6F01F009AE4A35CBC209B4AAB88D9DE8B191F78 | AA16: Branch Calendar Event | AC16: 1037 | AD16: 46221 | AE16: 46161 | AF16: 102 | AG16: 102 | AH16: 4.0 | AI16: FALSE | AJ16: 40bc320a-e99c-4f0e-b445-7c9c8f40198e | AK16: [Record] | AL16: [Table] | AM16: [Table] | AN16: [Record] | AO16: [Record] | AP16: [Record] | AQ16: [Record] | AR16: [Record] | AS16: [Record] | AT16: [Record] | AU16: [Record] | AV16: [Record] | AW16: [Record] | AX16: [Table] | AY16: [Record] | AZ16: [Record] | BA16: [Table] | BB16: [Record] | BC16: [Record] | BD16: [Record] | BI16: Cycling - Off Road - SP/TP (Brisbane)
A17: 0 | B17: 1039 | E17: Scouting Leadership (Online) | F17: Applications Close: 08/05/2026 Course Number: 1302604OL Course Fee: $ 80.00 Pre requisites: 6 months since completion of Scouting Adventure or Scouting Management Click here for the Training Program Outline Click here to apply for this training course This program will build on skills and knowledge gained through the delivery of youth program and deepen understanding of Scouting fundamentals. Note: Times listed are indicative only, refer to final course documentation for your course for confirmed course times. | G17: Low | J17: Calendar Entry | K17: 46058 | L17: 46058 | P17: [List] | Q17: [List] | S17: Training - AA | T17: 7373 | U17: 0x01006B96C2D89248E44D9DCCC3EFE7C6F01F009AE4A35CBC209B4AAB88D9DE8B191F78 | AA17: Branch Calendar Event | AC17: 1039 | AD17: 46221 | AE17: 46161 | AF17: 102 | AG17: 102 | AH17: 4.0 | AI17: FALSE | AJ17: 19f6ec85-8a49-483c-9d7c-b146d7a5c53e | AK17: [Record] | AL17: [Table] | AM17: [Table] | AN17: [Record] | AO17: [Record] | AP17: [Record] | AQ17: [Record] | AR17: [Record] | AS17: [Record] | AT17: [Record] | AU17: [Record] | AV17: [Record] | AW17: [Record] | AX17: [Table] | AY17: [Record] | AZ17: [Record] | BA17: [Table] | BB17: [Record] | BC17: [Record] | BD17: [Record] | BI17: Scouting Leadership (Online)
A18: 0 | B18: 1048 | E18: Cycling - Off Road - SP/TP (Wide Bay) | F18: Applications Close: 10/07/2026 Course Number: 0 Course Fee: $ 90.00 Pre requisites: Ability to ride a bike - Adult Supporters, Adult Leaders, Rover Scouts, Venturer Scouts Click here for the Training Program Outline Click here to apply for this training course This program will provide skills and knowledge to setup, maintain and repair a bicycle; plan routes; and ride off-road bicycles on easy to intermediate trails (eg mountain bike trails). Note: Times listed are indicative only and will be confirmed pre-course. | G18: Low | J18: Calendar Entry | K18: 46060 | L18: 46060 | P18: [List] | Q18: [List] | S18: Training - AA | T18: 7386 | U18: 0x01006B96C2D89248E44D9DCCC3EFE7C6F01F009AE4A35CBC209B4AAB88D9DE8B191F78 | AA18: Branch Calendar Event | AC18: 1048 | AD18: 46221 | AE18: 46161 | AF18: 102 | AG18: 102 | AH18: 4.0 | AI18: FALSE | AJ18: f1fbad35-7030-478e-b4c4-3fd041bb94b5 | AK18: [Record] | AL18: [Table] | AM18: [Table] | AN18: [Record] | AO18: [Record] | AP18: [Record] | AQ18: [Record] | AR18: [Record] | AS18: [Record] | AT18: [Record] | AU18: [Record] | AV18: [Record] | AW18: [Record] | AX18: [Table] | AY18: [Record] | AZ18: [Record] | BA18: [Table] | BB18: [Record] | BC18: [Record] | BD18: [Record] | BI18: Cycling - Off Road - SP/TP (Wide Bay)
A19: 0 | B19: 1025 | E19: Cycling - Off Road - SP/TP (Wide Bay) | F19: Applications Close: 10/07/2026 Course Number: 0 Course Fee: $ 90.00 Pre requisites: Ability to ride a bike - Adult Supporters, Adult Leaders, Rover Scouts, Venturer Scouts Click here for the Training Program Outline Click here to apply for this training course This program will provide skills and knowledge to setup, maintain and repair a bicycle; plan routes; and ride off-road bicycles on easy to intermediate trails (eg mountain bike trails). Note: Times listed are indicative only and will be confirmed pre-course. | G19: Low | J19: Calendar Entry | K19: 46060 | L19: 46060 | P19: [List] | Q19: [List] | T19: 7238 | U19: 0x01006B96C2D89248E44D9DCCC3EFE7C6F01F009AE4A35CBC209B4AAB88D9DE8B191F78 | AA19: Branch Calendar Event | AC19: 1025 | AD19: 46221 | AE19: 46161 | AF19: 102 | AG19: 102 | AH19: 4.0 | AI19: FALSE | AJ19: c1dcf8df-80df-49b0-ba05-24a3573d4ef6 | AK19: [Record] | AL19: [Table] | AM19: [Table] | AN19: [Record] | AO19: [Record] | AP19: [Record] | AQ19: [Record] | AR19: [Record] | AS19: [Record] | AT19: [Record] | AU19: [Record] | AV19: [Record] | AW19: [Record] | AX19: [Table] | AY19: [Record] | AZ19: [Record] | BA19: [Table] | BB19: [Record] | BC19: [Record] | BD19: [Record] | BI19: Cycling - Off Road - SP/TP (Wide Bay)
A20: 0 | B20: 1052 | E20: Scouting Adventure (Brisbane) | F20: Applications Close: 18/09/2026 Course Number: 1102612 Course Fee: $ 170.00 Pre requisites: Scouting Essentials and completion of Scouting Adventure On Demand learning Click here for the Training Program Outline Click here to apply for this training course This program will provide leaders of youth the skills and knowledge needed to support the delivery of the youth program to achieve Outdoor Adventure Skills Core Stage 3. Note: Times listed are indicative only, refer to final course documentation of your course for confirmed course times. | G20: Low | J20: Calendar Entry | K20: 46062 | L20: 46121 | P20: [List] | Q20: [List] | S20: Training - AA | T20: 7392 | U20: 0x01006B96C2D89248E44D9DCCC3EFE7C6F01F009AE4A35CBC209B4AAB88D9DE8B191F78 | AA20: Branch Calendar Event | AC20: 1052 | AD20: 46221 | AE20: 46161 | AF20: 102 | AG20: 102 | AH20: 4.0 | AI20: FALSE | AJ20: 86ddaab3-2062-4bd4-8f92-5bd4d9d17d02 | AK20: [Record] | AL20: [Table] | AM20: [Table] | AN20: [Record] | AO20: [Record] | AP20: [Record] | AQ20: [Record] | AR20: [Record] | AS20: [Record] | AT20: [Record] | AU20: [Record] | AV20: [Record] | AW20: [Record] | AX20: [Table] | AY20: [Record] | AZ20: [Record] | BA20: [Table] | BB20: [Record] | BC20: [Record] | BD20: [Record] | BI20: Scouting Adventure (Brisbane)
A21: 0 | B21: 1053 | E21: Scouting Essentials (Brisbane) | F21: Applications Close: 18/09/2026 Course Number: 1002614 Course Fee: $ 170.00 Pre requisites: Certificate of Adult Membership - Adult Leaders, Rover Scouts Click here for the Training Program Outline Click here to apply for this training course This program will provide the skills and knowledge needed to plan and deliver activities to implement the Youth Program at weekly meetings and overnight activities. Note: Times listed are indicative only, refer to final course documentation for your course for confirmed course times. | G21: Low | J21: Calendar Entry | K21: 46062 | L21: 46121 | P21: [List] | Q21: [List] | S21: Training - AA | T21: 7393 | U21: 0x01006B96C2D89248E44D9DCCC3EFE7C6F01F009AE4A35CBC209B4AAB88D9DE8B191F78 | AA21: Branch Calendar Event | AC21: 1053 | AD21: 46221 | AE21: 46161 | AF21: 102 | AG21: 102 | AH21: 4.0 | AI21: FALSE | AJ21: a6158a61-e35e-4450-b5d3-24f52bba697d | AK21: [Record] | AL21: [Table] | AM21: [Table] | AN21: [Record] | AO21: [Record] | AP21: [Record] | AQ21: [Record] | AR21: [Record] | AS21: [Record] | AT21: [Record] | AU21: [Record] | AV21: [Record] | AW21: [Record] | AX21: [Table] | AY21: [Record] | AZ21: [Record] | BA21: [Table] | BB21: [Record] | BC21: [Record] | BD21: [Record] | BI21: Scouting Essentials (Brisbane)
A22: 0 | B22: 1029 | E22: Scouting Adventure (Brisbane) | F22: Applications Close: 18/09/2026 Course Number: 1102612 Course Fee: $ 170.00 Pre requisites: Scouting Essentials and completion of Scouting Adventure On Demand learning Click here for the Training Program Outline Click here to apply for this training course This program will provide leaders of youth the skills and knowledge needed to support the delivery of the youth program to achieve Outdoor Adventure Skills Core Stage 3. Note: Times listed are indicative only, refer to final course documentation of your course for confirmed course times. | G22: Low | J22: Calendar Entry | K22: 46062 | L22: 46121 | P22: [List] | Q22: [List] | T22: 7247 | U22: 0x01006B96C2D89248E44D9DCCC3EFE7C6F01F009AE4A35CBC209B4AAB88D9DE8B191F78 | AA22: Branch Calendar Event | AC22: 1029 | AD22: 46221 | AE22: 46161 | AF22: 102 | AG22: 102 | AH22: 4.0 | AI22: FALSE | AJ22: 461651b3-f865-4f87-a53e-a62a0fec89da | AK22: [Record] | AL22: [Table] | AM22: [Table] | AN22: [Record] | AO22: [Record] | AP22: [Record] | AQ22: [Record] | AR22: [Record] | AS22: [Record] | AT22: [Record] | AU22: [Record] | AV22: [Record] | AW22: [Record] | AX22: [Table] | AY22: [Record] | AZ22: [Record] | BA22: [Table] | BB22: [Record] | BC22: [Record] | BD22: [Record] | BI22: Scouting Adventure (Brisbane)
A23: 0 | B23: 1030 | E23: Scouting Essentials (Brisbane) | F23: Applications Close: 18/09/2026 Course Number: 1002614 Course Fee: $ 170.00 Pre requisites: Certificate of Adult Membership - Adult Leaders, Rover Scouts Click here for the Training Program Outline Click here to apply for this training course This program will provide the skills and knowledge needed to plan and deliver activities to implement the Youth Program at weekly meetings and overnight activities. Note: Times listed are indicative only, refer to final course documentation for your course for confirmed course times. | G23: Low | J23: Calendar Entry | K23: 46062 | L23: 46121 | P23: [List] | Q23: [List] | T23: 7248 | U23: 0x01006B96C2D89248E44D9DCCC3EFE7C6F01F009AE4A35CBC209B4AAB88D9DE8B191F78 | AA23: Branch Calendar Event | AC23: 1030 | AD23: 46221 | AE23: 46161 | AF23: 102 | AG23: 102 | AH23: 4.0 | AI23: FALSE | AJ23: b8f36462-1bce-4be1-b5ec-0b396c4b3768 | AK23: [Record] | AL23: [Table] | AM23: [Table] | AN23: [Record] | AO23: [Record] | AP23: [Record] | AQ23: [Record] | AR23: [Record] | AS23: [Record] | AT23: [Record] | AU23: [Record] | AV23: [Record] | AW23: [Record] | AX23: [Table] | AY23: [Record] | AZ23: [Record] | BA23: [Table] | BB23: [Record] | BC23: [Record] | BD23: [Record] | BI23: Scouting Essentials (Brisbane)
A24: 0 | B24: 992 | E24: Queensland Branch Rover Council Meeting | F24: Monthly | G24: Low | J24: Calendar Entry | K24: 46067 | L24: 46067 | P24: [List] | Q24: [List] | S24: Rover Scouts | T24: 5782 | U24: 0x01006B96C2D89248E44D9DCCC3EFE7C6F01F009AE4A35CBC209B4AAB88D9DE8B191F78 | AA24: Branch Calendar Event | AC24: 992 | AD24: 46221 | AE24: 46161 | AF24: 102 | AG24: 102 | AH24: 4.0 | AI24: FALSE | AJ24: 62765f15-cf9d-47a1-aa97-17d339875b43 | AK24: [Record] | AL24: [Table] | AM24: [Table] | AN24: [Record] | AO24: [Record] | AP24: [Record] | AQ24: [Record] | AR24: [Record] | AS24: [Record] | AT24: [Record] | AU24: [Record] | AV24: [Record] | AW24: [Record] | AX24: [Table] | AY24: [Record] | AZ24: [Record] | BA24: [Table] | BB24: [Record] | BC24: [Record] | BD24: [Record] | BI24: Queensland Branch Rover Council Meeting
A25: 0 | B25: 951 | E25: Branch Finance Committee | F25: 3rd Monday of the month | G25: Low | J25: Calendar Entry | K25: 46068 | L25: 46068 | P25: [List] | Q25: [List] | T25: 5741 | U25: 0x01006B96C2D89248E44D9DCCC3EFE7C6F01F009AE4A35CBC209B4AAB88D9DE8B191F78 | AA25: Branch Calendar Event | AC25: 951 | AD25: 46221 | AE25: 46161 | AF25: 102 | AG25: 102 | AH25: 4.0 | AI25: FALSE | AJ25: 89c08ccb-06c4-41b5-b457-fe729493d3a0 | AK25: [Record] | AL25: [Table] | AM25: [Table] | AN25: [Record] | AO25: [Record] | AP25: [Record] | AQ25: [Record] | AR25: [Record] | AS25: [Record] | AT25: [Record] | AU25: [Record] | AV25: [Record] | AW25: [Record] | AX25: [Table] | AY25: [Record] | AZ25: [Record] | BA25: [Table] | BB25: [Record] | BC25: [Record] | BD25: [Record] | BI25: Branch Finance Committee
A26: 0 | B26: 971 | E26: Branch Scout Section Council | F26: Monthly | G26: Low | J26: Calendar Entry | K26: 46068 | L26: 46068 | P26: [List] | Q26: [List] | T26: 5761 | U26: 0x01006B96C2D89248E44D9DCCC3EFE7C6F01F009AE4A35CBC209B4AAB88D9DE8B191F78 | Z26: BC Joey Scouts | AA26: Branch Calendar Event | AC26: 971 | AD26: 46221 | AE26: 46161 | AF26: 102 | AG26: 102 | AH26: 5.0 | AI26: FALSE | AJ26: ab57b248-e204-4efd-8a75-cde76fb7aae6 | AK26: [Record] | AL26: [Table] | AM26: [Table] | AN26: [Record] | AO26: [Record] | AP26: [Record] | AQ26: [Record] | AR26: [Record] | AS26: [Record] | AT26: [Record] | AU26: [Record] | AV26: [Record] | AW26: [Record] | AX26: [Table] | AY26: [Record] | AZ26: [Record] | BA26: [Table] | BB26: [Record] | BC26: [Record] | BD26: [Record] | BI26: Branch Scout Section Council
A27: 0 | B27: 980 | E27: Branch Youth Venturer Scout Council | F27: Monthly | G27: Low | J27: Calendar Entry | K27: 46070 | L27: 46070 | P27: [List] | Q27: [List] | T27: 5770 | U27: 0x01006B96C2D89248E44D9DCCC3EFE7C6F01F009AE4A35CBC209B4AAB88D9DE8B191F78 | AA27: Branch Calendar Event | AC27: 980 | AD27: 46221 | AE27: 46161 | AF27: 102 | AG27: 102 | AH27: 4.0 | AI27: FALSE | AJ27: 2a9a3e4f-e0a4-4681-876f-f33202fcaa46 | AK27: [Record] | AL27: [Table] | AM27: [Table] | AN27: [Record] | AO27: [Record] | AP27: [Record] | AQ27: [Record] | AR27: [Record] | AS27: [Record] | AT27: [Record] | AU27: [Record] | AV27: [Record] | AW27: [Record] | AX27: [Table] | AY27: [Record] | AZ27: [Record] | BA27: [Table] | BB27: [Record] | BC27: [Record] | BD27: [Record] | BI27: Branch Youth Venturer Scout Council
A28: 0 | B28: 963 | E28: Branch Joey Scout Council | F28: Monthly | G28: Low | J28: Calendar Entry | K28: 46070 | L28: 46070 | P28: [List] | Q28: [List] | S28: Joey Scouts | T28: 5753 | U28: 0x01006B96C2D89248E44D9DCCC3EFE7C6F01F009AE4A35CBC209B4AAB88D9DE8B191F78 | Z28: BC Joey Scouts | AA28: Branch Calendar Event | AC28: 963 | AD28: 46221 | AE28: 46161 | AF28: 102 | AG28: 102 | AH28: 5.0 | AI28: FALSE | AJ28: 1bc404c7-8dc6-498c-879b-9c7a2ed4afdd | AK28: [Record] | AL28: [Table] | AM28: [Table] | AN28: [Record] | AO28: [Record] | AP28: [Record] | AQ28: [Record] | AR28: [Record] | AS28: [Record] | AT28: [Record] | AU28: [Record] | AV28: [Record] | AW28: [Record] | AX28: [Table] | AY28: [Record] | AZ28: [Record] | BA28: [Table] | BB28: [Record] | BC28: [Record] | BD28: [Record] | BI28: Branch Joey Scout Council
A29: 0 | B29: 928 | E29: Branch Cub Scout Section Team Meeting | F29: Monthly | G29: Low | J29: Calendar Entry | K29: 46071 | L29: 46071 | P29: [List] | Q29: [List] | T29: 5718 | U29: 0x01006B96C2D89248E44D9DCCC3EFE7C6F01F009AE4A35CBC209B4AAB88D9DE8B191F78 | AA29: Branch Calendar Event | AC29: 928 | AD29: 46221 | AE29: 46161 | AF29: 102 | AG29: 102 | AH29: 4.0 | AI29: FALSE | AJ29: 4f0c95fb-7bb9-443c-960f-0f759cd57086 | AK29: [Record] | AL29: [Table] | AM29: [Table] | AN29: [Record] | AO29: [Record] | AP29: [Record] | AQ29: [Record] | AR29: [Record] | AS29: [Record] | AT29: [Record] | AU29: [Record] | AV29: [Record] | AW29: [Record] | AX29: [Table] | AY29: [Record] | AZ29: [Record] | BA29: [Table] | BB29: [Record] | BC29: [Record] | BD29: [Record] | BI29: Branch Cub Scout Section Team Meeting
